2025-06-21 12:50:11,445 ERROR: Failed to send email: (535, b'5.7.8 Username and Password not accepted. For more information, go to\n5.7.8  https://support.google.com/mail/?p=BadCredentials ffacd0b85a97d-3a6d0f1808bsm4244252f8f.24 - gsmtp') [in c:\Users\ADMIN\leave_app_system\backend\app\staff\routes.py:231]
2025-06-21 12:52:12,788 ERROR: Failed to send email: (535, b'5.7.8 Username and Password not accepted. For more information, go to\n5.7.8  https://support.google.com/mail/?p=BadCredentials 5b1f17b1804b1-4535ead202asm82317235e9.27 - gsmtp') [in c:\Users\ADMIN\leave_app_system\backend\app\staff\routes.py:231]
2025-06-21 12:57:01,554 ERROR: Email sending failed: (535, b'5.7.8 Username and Password not accepted. For more information, go to\n5.7.8  https://support.google.com/mail/?p=BadCredentials ffacd0b85a97d-3a6d0f10558sm4326915f8f.16 - gsmtp') [in c:\Users\ADMIN\leave_app_system\backend\app\staff\routes.py:237]
2025-06-21 13:26:04,387 ERROR: Password reset error: (535, b'5.7.8 Username and Password not accepted. For more information, go to\n5.7.8  https://support.google.com/mail/?p=BadCredentials 5b1f17b1804b1-453646fd74asm49456205e9.22 - gsmtp') [in c:\Users\ADMIN\leave_app_system\backend\app\staff\routes.py:272]
2025-06-21 13:38:10,798 ERROR: Password reset error: staff/reset_password.html [in c:\Users\ADMIN\leave_app_system\backend\app\staff\routes.py:323]
2025-06-21 13:38:32,392 ERROR: Password reset error: staff/reset_password.html [in c:\Users\ADMIN\leave_app_system\backend\app\staff\routes.py:323]
2025-06-21 13:44:41,470 ERROR: Token validation failed: Signature b'ZWBif43D4dpysrVUPQpuoXIj-Dc' does not match [in c:\Users\ADMIN\leave_app_system\backend\app\staff\routes.py:309]
2025-06-21 13:44:49,760 ERROR: Token validation failed: staff/reset_password.html [in c:\Users\ADMIN\leave_app_system\backend\app\staff\routes.py:309]
2025-06-21 13:46:53,110 ERROR: Password reset error: Signature b'ZWBif43D4dpysrVUPQpuoXIj-Dc' does not match [in c:\Users\ADMIN\leave_app_system\backend\app\staff\routes.py:340]
2025-06-21 13:47:02,497 ERROR: Password reset error: Signature b'ZWBif43D4dpysrVUPQpuoXIj-Dc' does not match [in c:\Users\ADMIN\leave_app_system\backend\app\staff\routes.py:340]
2025-06-21 13:47:44,218 ERROR: Password reset error: Signature b'ZWBif43D4dpysrVUPQpuoXIj-Dc' does not match [in c:\Users\ADMIN\leave_app_system\backend\app\staff\routes.py:340]
2025-06-21 13:49:47,300 ERROR: Password reset failed: {'error': "Signature b'ZWBif43D4dpysrVUPQpuoXIj-Dc' does not match", 'email': None, 'timestamp': '2025-06-21T10:49:47.300522'} [in c:\Users\ADMIN\leave_app_system\backend\app\staff\routes.py:364]
2025-06-21 13:53:20,412 ERROR: Password reset failed: {'error': 'staff/reset_password.html', 'email': 'clivemisiko01@gmail.com', 'timestamp': '2025-06-21T10:53:20.412010'} [in c:\Users\ADMIN\leave_app_system\backend\app\staff\routes.py:364]
2025-06-21 13:55:17,268 INFO: Token decoded for email: clivemisiko01@gmail.com [in c:\Users\ADMIN\leave_app_system\backend\app\staff\routes.py:303]
2025-06-21 13:55:17,273 CRITICAL: Unexpected error: staff/reset_password.html [in c:\Users\ADMIN\leave_app_system\backend\app\staff\routes.py:382]
Traceback (most recent call last):
  File "c:\Users\ADMIN\leave_app_system\backend\app\staff\routes.py", line 379, in reset_password
    return render_template('staff/reset_password.html', token=token)
  File "C:\Users\ADMIN\leave_app_system\venv\Lib\site-packages\flask\templating.py", line 149, in render_template
    template = app.jinja_env.get_or_select_template(template_name_or_list)
  File "C:\Users\ADMIN\leave_app_system\venv\Lib\site-packages\jinja2\environment.py", line 1087, in get_or_select_template
    return self.get_template(template_name_or_list, parent, globals)
           ~~~~~~~~~~~~~~~~~^^^^^^^^^^^^^^^^^^^^^^^^^^^^^^^^^^^^^^^^
  File "C:\Users\ADMIN\leave_app_system\venv\Lib\site-packages\jinja2\environment.py", line 1016, in get_template
    return self._load_template(name, globals)
           ~~~~~~~~~~~~~~~~~~~^^^^^^^^^^^^^^^
  File "C:\Users\ADMIN\leave_app_system\venv\Lib\site-packages\jinja2\environment.py", line 975, in _load_template
    template = self.loader.load(self, name, self.make_globals(globals))
  File "C:\Users\ADMIN\leave_app_system\venv\Lib\site-packages\jinja2\loaders.py", line 126, in load
    source, filename, uptodate = self.get_source(environment, name)
                                 ~~~~~~~~~~~~~~~^^^^^^^^^^^^^^^^^^^
  File "C:\Users\ADMIN\leave_app_system\venv\Lib\site-packages\flask\templating.py", line 65, in get_source
    return self._get_source_fast(environment, template)
           ~~~~~~~~~~~~~~~~~~~~~^^^^^^^^^^^^^^^^^^^^^^^
  File "C:\Users\ADMIN\leave_app_system\venv\Lib\site-packages\flask\templating.py", line 99, in _get_source_fast
    raise TemplateNotFound(template)
jinja2.exceptions.TemplateNotFound: staff/reset_password.html
2025-06-21 13:55:45,643 INFO: Token decoded for email: clivemisiko01@gmail.com [in c:\Users\ADMIN\leave_app_system\backend\app\staff\routes.py:303]
2025-06-21 13:55:45,647 WARNING: Token mismatch for: clivemisiko01@gmail.com [in c:\Users\ADMIN\leave_app_system\backend\app\staff\routes.py:325]
2025-06-21 14:03:57,349 INFO: Password reset sent to clivemisiko01@gmail.com [in c:\Users\ADMIN\leave_app_system\backend\app\staff\routes.py:273]
2025-06-21 14:04:04,867 WARNING: Invalid token for clivemisiko01@gmail.com [in c:\Users\ADMIN\leave_app_system\backend\app\staff\routes.py:316]
2025-06-21 14:08:12,907 WARNING: Token not found for email: clivemisiko01@gmail.com [in c:\Users\ADMIN\leave_app_system\backend\app\staff\routes.py:308]
2025-06-23 08:37:19,564 ERROR: Token validation failed: staff/reset_password.html [in c:\Users\ADMIN\leave_app_system\backend\app\staff\routes.py:343]
2025-06-23 08:37:47,849 ERROR: Invalid token for clivemisiko01@gmail.com [in c:\Users\ADMIN\leave_app_system\backend\app\staff\routes.py:312]
2025-06-23 08:37:50,349 ERROR: Token validation failed: staff/reset_password.html [in c:\Users\ADMIN\leave_app_system\backend\app\staff\routes.py:343]
2025-06-23 08:42:17,626 ERROR: Token validation failed: staff/reset_password.html [in c:\Users\ADMIN\leave_app_system\backend\app\staff\routes.py:342]
2025-06-23 08:42:21,528 ERROR: Invalid token for clivemisiko01@gmail.com [in c:\Users\ADMIN\leave_app_system\backend\app\staff\routes.py:312]
2025-06-23 08:42:25,461 ERROR: Invalid token for clivemisiko01@gmail.com [in c:\Users\ADMIN\leave_app_system\backend\app\staff\routes.py:312]
2025-06-23 08:42:38,635 ERROR: Token validation failed: staff/reset_password.html [in c:\Users\ADMIN\leave_app_system\backend\app\staff\routes.py:342]
2025-06-23 08:48:04,756 ERROR: Token validation failed: staff/reset_password.html [in c:\Users\ADMIN\leave_app_system\backend\app\staff\routes.py:342]
2025-06-23 17:29:44,339 ERROR: Error sending reset email: [Errno 11001] getaddrinfo failed [in c:\Users\ADMIN\leave_app_system\backend\app\staff\routes.py:285]
2025-06-27 20:37:54,934 ERROR: Registration error: (1146, "Table 'railway.staff' doesn't exist") [in c:\Users\ADMIN\leave_app_system\backend\app\staff\routes.py:170]
2025-06-27 20:38:13,442 ERROR: Login error: (1146, "Table 'railway.staff' doesn't exist") [in c:\Users\ADMIN\leave_app_system\backend\app\staff\routes.py:214]
2025-07-01 08:46:01,672 ERROR: Print failed: (1054, "Unknown column 's.designation' in 'field list'") [in c:\Users\ADMIN\leave_app_system\backend\app\staff\routes.py:563]
Traceback (most recent call last):
  File "c:\Users\ADMIN\leave_app_system\backend\app\staff\routes.py", line 516, in print_application
    cur.execute("""
    ~~~~~~~~~~~^^^^
        SELECT la.*, s.designation, s.leave_balance
        ^^^^^^^^^^^^^^^^^^^^^^^^^^^^^^^^^^^^^^^^^^^
    ...<2 lines>...
        WHERE la.id = %s AND la.staff_id = %s
        ^^^^^^^^^^^^^^^^^^^^^^^^^^^^^^^^^^^^^
    """, (app_id, staff_id))
    ^^^^^^^^^^^^^^^^^^^^^^^^
  File "C:\Users\ADMIN\leave_app_system\venv\Lib\site-packages\pymysql\cursors.py", line 153, in execute
    result = self._query(query)
  File "C:\Users\ADMIN\leave_app_system\venv\Lib\site-packages\pymysql\cursors.py", line 322, in _query
    conn.query(q)
    ~~~~~~~~~~^^^
  File "C:\Users\ADMIN\leave_app_system\venv\Lib\site-packages\pymysql\connections.py", line 563, in query
    self._affected_rows = self._read_query_result(unbuffered=unbuffered)
                          ~~~~~~~~~~~~~~~~~~~~~~~^^^^^^^^^^^^^^^^^^^^^^^
  File "C:\Users\ADMIN\leave_app_system\venv\Lib\site-packages\pymysql\connections.py", line 825, in _read_query_result
    result.read()
    ~~~~~~~~~~~^^
  File "C:\Users\ADMIN\leave_app_system\venv\Lib\site-packages\pymysql\connections.py", line 1199, in read
    first_packet = self.connection._read_packet()
  File "C:\Users\ADMIN\leave_app_system\venv\Lib\site-packages\pymysql\connections.py", line 775, in _read_packet
    packet.raise_for_error()
    ~~~~~~~~~~~~~~~~~~~~~~^^
  File "C:\Users\ADMIN\leave_app_system\venv\Lib\site-packages\pymysql\protocol.py", line 219, in raise_for_error
    err.raise_mysql_exception(self._data)
    ~~~~~~~~~~~~~~~~~~~~~~~~~^^^^^^^^^^^^
  File "C:\Users\ADMIN\leave_app_system\venv\Lib\site-packages\pymysql\err.py", line 150, in raise_mysql_exception
    raise errorclass(errno, errval)
pymysql.err.OperationalError: (1054, "Unknown column 's.designation' in 'field list'")
2025-07-01 08:49:04,568 ERROR: Logo file not found at: c:\Users\ADMIN\leave_app_system\backend\app\static\images\gov_logo.png [in c:\Users\ADMIN\leave_app_system\backend\app\admin\utils\images.py:10]
2025-07-01 08:49:04,570 WARNING: Logo file not found or could not be loaded [in c:\Users\ADMIN\leave_app_system\backend\app\admin\routes.py:421]
2025-07-01 08:49:10,176 ERROR: Logo file not found at: c:\Users\ADMIN\leave_app_system\backend\app\static\images\gov_logo.png [in c:\Users\ADMIN\leave_app_system\backend\app\admin\utils\images.py:10]
2025-07-01 08:49:10,177 WARNING: Logo file not found or could not be loaded [in c:\Users\ADMIN\leave_app_system\backend\app\admin\routes.py:421]
2025-07-01 08:52:26,258 ERROR: Logo file not found at: c:\Users\ADMIN\leave_app_system\backend\app\static\images\gov_logo.png [in c:\Users\ADMIN\leave_app_system\backend\app\admin\utils\images.py:10]
2025-07-01 08:52:26,262 WARNING: Logo file not found or could not be loaded [in c:\Users\ADMIN\leave_app_system\backend\app\admin\routes.py:421]
2025-07-01 08:52:28,978 ERROR: Logo file not found at: c:\Users\ADMIN\leave_app_system\backend\app\static\images\gov_logo.png [in c:\Users\ADMIN\leave_app_system\backend\app\admin\utils\images.py:10]
2025-07-01 08:52:28,981 WARNING: Logo file not found or could not be loaded [in c:\Users\ADMIN\leave_app_system\backend\app\admin\routes.py:421]
2025-07-01 08:53:32,839 ERROR: Print failed: (1054, "Unknown column 's.designation' in 'field list'") [in c:\Users\ADMIN\leave_app_system\backend\app\staff\routes.py:563]
Traceback (most recent call last):
  File "c:\Users\ADMIN\leave_app_system\backend\app\staff\routes.py", line 516, in print_application
    cur.execute("""
    ~~~~~~~~~~~^^^^
        SELECT la.*, s.designation, s.leave_balance
        ^^^^^^^^^^^^^^^^^^^^^^^^^^^^^^^^^^^^^^^^^^^
    ...<2 lines>...
        WHERE la.id = %s AND la.staff_id = %s
        ^^^^^^^^^^^^^^^^^^^^^^^^^^^^^^^^^^^^^
    """, (app_id, staff_id))
    ^^^^^^^^^^^^^^^^^^^^^^^^
  File "C:\Users\ADMIN\leave_app_system\venv\Lib\site-packages\pymysql\cursors.py", line 153, in execute
    result = self._query(query)
  File "C:\Users\ADMIN\leave_app_system\venv\Lib\site-packages\pymysql\cursors.py", line 322, in _query
    conn.query(q)
    ~~~~~~~~~~^^^
  File "C:\Users\ADMIN\leave_app_system\venv\Lib\site-packages\pymysql\connections.py", line 563, in query
    self._affected_rows = self._read_query_result(unbuffered=unbuffered)
                          ~~~~~~~~~~~~~~~~~~~~~~~^^^^^^^^^^^^^^^^^^^^^^^
  File "C:\Users\ADMIN\leave_app_system\venv\Lib\site-packages\pymysql\connections.py", line 825, in _read_query_result
    result.read()
    ~~~~~~~~~~~^^
  File "C:\Users\ADMIN\leave_app_system\venv\Lib\site-packages\pymysql\connections.py", line 1199, in read
    first_packet = self.connection._read_packet()
  File "C:\Users\ADMIN\leave_app_system\venv\Lib\site-packages\pymysql\connections.py", line 775, in _read_packet
    packet.raise_for_error()
    ~~~~~~~~~~~~~~~~~~~~~~^^
  File "C:\Users\ADMIN\leave_app_system\venv\Lib\site-packages\pymysql\protocol.py", line 219, in raise_for_error
    err.raise_mysql_exception(self._data)
    ~~~~~~~~~~~~~~~~~~~~~~~~~^^^^^^^^^^^^
  File "C:\Users\ADMIN\leave_app_system\venv\Lib\site-packages\pymysql\err.py", line 150, in raise_mysql_exception
    raise errorclass(errno, errval)
pymysql.err.OperationalError: (1054, "Unknown column 's.designation' in 'field list'")
2025-07-01 09:03:16,888 ERROR: Print failed: (1054, "Unknown column 's.designation' in 'field list'") [in c:\Users\ADMIN\leave_app_system\backend\app\staff\routes.py:562]
Traceback (most recent call last):
  File "c:\Users\ADMIN\leave_app_system\backend\app\staff\routes.py", line 516, in print_application
    cur.execute("""
    ~~~~~~~~~~~^^^^
        SELECT la.*, s.designation, s.leave_balance
        ^^^^^^^^^^^^^^^^^^^^^^^^^^^^^^^^^^^^^^^^^^^
    ...<2 lines>...
        WHERE la.id = %s AND la.staff_id = %s
        ^^^^^^^^^^^^^^^^^^^^^^^^^^^^^^^^^^^^^
    """, (app_id, staff_id))
    ^^^^^^^^^^^^^^^^^^^^^^^^
  File "C:\Users\ADMIN\leave_app_system\venv\Lib\site-packages\pymysql\cursors.py", line 153, in execute
    result = self._query(query)
  File "C:\Users\ADMIN\leave_app_system\venv\Lib\site-packages\pymysql\cursors.py", line 322, in _query
    conn.query(q)
    ~~~~~~~~~~^^^
  File "C:\Users\ADMIN\leave_app_system\venv\Lib\site-packages\pymysql\connections.py", line 563, in query
    self._affected_rows = self._read_query_result(unbuffered=unbuffered)
                          ~~~~~~~~~~~~~~~~~~~~~~~^^^^^^^^^^^^^^^^^^^^^^^
  File "C:\Users\ADMIN\leave_app_system\venv\Lib\site-packages\pymysql\connections.py", line 825, in _read_query_result
    result.read()
    ~~~~~~~~~~~^^
  File "C:\Users\ADMIN\leave_app_system\venv\Lib\site-packages\pymysql\connections.py", line 1199, in read
    first_packet = self.connection._read_packet()
  File "C:\Users\ADMIN\leave_app_system\venv\Lib\site-packages\pymysql\connections.py", line 775, in _read_packet
    packet.raise_for_error()
    ~~~~~~~~~~~~~~~~~~~~~~^^
  File "C:\Users\ADMIN\leave_app_system\venv\Lib\site-packages\pymysql\protocol.py", line 219, in raise_for_error
    err.raise_mysql_exception(self._data)
    ~~~~~~~~~~~~~~~~~~~~~~~~~^^^^^^^^^^^^
  File "C:\Users\ADMIN\leave_app_system\venv\Lib\site-packages\pymysql\err.py", line 150, in raise_mysql_exception
    raise errorclass(errno, errval)
pymysql.err.OperationalError: (1054, "Unknown column 's.designation' in 'field list'")
2025-07-01 09:03:27,136 WARNING: Logo file not found or could not be loaded [in c:\Users\ADMIN\leave_app_system\backend\app\admin\routes.py:431]
2025-07-01 09:03:30,009 WARNING: Logo file not found or could not be loaded [in c:\Users\ADMIN\leave_app_system\backend\app\admin\routes.py:431]
